Workbook

Sheet Сводка
A1: ПЛАН-ФАКТ ПОЛЕВЫХ РАБОТ 2026
A2: На 24.05.2026 · собрано автоматически из листа «Общий свод 2026» · все числа — формулы к листам «Данные» и «Выработка»
A4: Вид работ | B4: План, га | C4: Факт, га | D4: Остаток, га | E4: Выполнение | F4: Статус | G4: Позиций
A5: Хим обработка | B5: =SUMIF(Данные!$B$5:$B$62,$A5,Данные!$F$5:$F$62) | C5: =SUMIF(Данные!$B$5:$B$62,$A5,Данные!$G$5:$G$62) | D5: =B5-C5 | E5: =IFERROR(C5/B5,0) | F5: =IF(E5>=0.995,"завершено",IF(E5>=0.7,"в графике",IF(E5>=0.35,"отставание","срыв срока"))) | G5: =COUNTIF(Данные!$B$5:$B$62,$A5)
A6: Хим обработка №2 | B6: =SUMIF(Данные!$B$5:$B$62,$A6,Данные!$F$5:$F$62) | C6: =SUMIF(Данные!$B$5:$B$62,$A6,Данные!$G$5:$G$62) | D6: =B6-C6 | E6: =IFERROR(C6/B6,0) | F6: =IF(E6>=0.995,"завершено",IF(E6>=0.7,"в графике",IF(E6>=0.35,"отставание","срыв срока"))) | G6: =COUNTIF(Данные!$B$5:$B$62,$A6)
A7: Внесение мин.удобрений №1 | B7: =SUMIF(Данные!$B$5:$B$62,$A7,Данные!$F$5:$F$62) | C7: =SUMIF(Данные!$B$5:$B$62,$A7,Данные!$G$5:$G$62) | D7: =B7-C7 | E7: =IFERROR(C7/B7,0) | F7: =IF(E7>=0.995,"завершено",IF(E7>=0.7,"в графике",IF(E7>=0.35,"отставание","срыв срока"))) | G7: =COUNTIF(Данные!$B$5:$B$62,$A7)
A8: Внесение мин.удобрений №2 | B8: =SUMIF(Данные!$B$5:$B$62,$A8,Данные!$F$5:$F$62) | C8: =SUMIF(Данные!$B$5:$B$62,$A8,Данные!$G$5:$G$62) | D8: =B8-C8 | E8: =IFERROR(C8/B8,0) | F8: =IF(E8>=0.995,"завершено",IF(E8>=0.7,"в графике",IF(E8>=0.35,"отставание","срыв срока"))) | G8: =COUNTIF(Данные!$B$5:$B$62,$A8)
A9: Предпосевная культивация | B9: =SUMIF(Данные!$B$5:$B$62,$A9,Данные!$F$5:$F$62) | C9: =SUMIF(Данные!$B$5:$B$62,$A9,Данные!$G$5:$G$62) | D9: =B9-C9 | E9: =IFERROR(C9/B9,0) | F9: =IF(E9>=0.995,"завершено",IF(E9>=0.7,"в графике",IF(E9>=0.35,"отставание","срыв срока"))) | G9: =COUNTIF(Данные!$B$5:$B$62,$A9)
A10: Сев горошка | B10: =SUMIF(Данные!$B$5:$B$62,$A10,Данные!$F$5:$F$62) | C10: =SUMIF(Данные!$B$5:$B$62,$A10,Данные!$G$5:$G$62) | D10: =B10-C10 | E10: =IFERROR(C10/B10,0) | F10: =IF(E10>=0.995,"завершено",IF(E10>=0.7,"в графике",IF(E10>=0.35,"отставание","срыв срока"))) | G10: =COUNTIF(Данные!$B$5:$B$62,$A10)
A11: Сев зерновых | B11: =SUMIF(Данные!$B$5:$B$62,$A11,Данные!$F$5:$F$62) | C11: =SUMIF(Данные!$B$5:$B$62,$A11,Данные!$G$5:$G$62) | D11: =B11-C11 | E11: =IFERROR(C11/B11,0) | F11: =IF(E11>=0.995,"завершено",IF(E11>=0.7,"в графике",IF(E11>=0.35,"отставание","срыв срока"))) | G11: =COUNTIF(Данные!$B$5:$B$62,$A11)
A12: Культивация№1 | B12: =SUMIF(Данные!$B$5:$B$62,$A12,Данные!$F$5:$F$62) | C12: =SUMIF(Данные!$B$5:$B$62,$A12,Данные!$G$5:$G$62) | D12: =B12-C12 | E12: =IFERROR(C12/B12,0) | F12: =IF(E12>=0.995,"завершено",IF(E12>=0.7,"в графике",IF(E12>=0.35,"отставание","срыв срока"))) | G12: =COUNTIF(Данные!$B$5:$B$62,$A12)
A13: Культивация№111 | B13: =SUMIF(Данные!$B$5:$B$62,$A13,Данные!$F$5:$F$62) | C13: =SUMIF(Данные!$B$5:$B$62,$A13,Данные!$G$5:$G$62) | D13: =B13-C13 | E13: =IFERROR(C13/B13,0) | F13: =IF(E13>=0.995,"завершено",IF(E13>=0.7,"в графике",IF(E13>=0.35,"отставание","срыв срока"))) | G13: =COUNTIF(Данные!$B$5:$B$62,$A13)
A14: СЕВ СЛАДКОЙ КУКУРУЗЫ | B14: =SUMIF(Данные!$B$5:$B$62,$A14,Данные!$F$5:$F$62) | C14: =SUMIF(Данные!$B$5:$B$62,$A14,Данные!$G$5:$G$62) | D14: =B14-C14 | E14: =IFERROR(C14/B14,0) | F14: =IF(E14>=0.995,"завершено",IF(E14>=0.7,"в графике",IF(E14>=0.35,"отставание","срыв срока"))) | G14: =COUNTIF(Данные!$B$5:$B$62,$A14)
A15: Прикатывание до всходов | B15: =SUMIF(Данные!$B$5:$B$62,$A15,Данные!$F$5:$F$62) | C15: =SUMIF(Данные!$B$5:$B$62,$A15,Данные!$G$5:$G$62) | D15: =B15-C15 | E15: =IFERROR(C15/B15,0) | F15: =IF(E15>=0.995,"завершено",IF(E15>=0.7,"в графике",IF(E15>=0.35,"отставание","срыв срока"))) | G15: =COUNTIF(Данные!$B$5:$B$62,$A15)
A16: Культивация№2 | B16: =SUMIF(Данные!$B$5:$B$62,$A16,Данные!$F$5:$F$62) | C16: =SUMIF(Данные!$B$5:$B$62,$A16,Данные!$G$5:$G$62) | D16: =B16-C16 | E16: =IFERROR(C16/B16,0) | F16: =IF(E16>=0.995,"завершено",IF(E16>=0.7,"в графике",IF(E16>=0.35,"отставание","срыв срока"))) | G16: =COUNTIF(Данные!$B$5:$B$62,$A16)
... A18: Глубокое рыхление 40-45 | B18: =SUMIF(Данные!$B$5:$B$62,$A18,Данные!$F$5:$F$62) | C18: =SUMIF(Данные!$B$5:$B$62,$A18,Данные!$G$5:$G$62) | D18: =B18-C18 | E18: =IFERROR(C18/B18,0) | F18: =IF(E18>=0.995,"завершено",IF(E18>=0.7,"в графике",IF(E18>=0.35,"отставание","срыв срока"))) | G18: =COUNTIF(Данные!$B$5:$B$62,$A18)
A19: ИТОГО ПО ПРЕДПРИЯТИЮ | B19: =SUM(B5:B18) | C19: =SUM(C5:C18) | D19: =B19-C19 | E19: =IFERROR(C19/B19,0) | G19: =SUM(G5:G18)

Sheet По дням
A1: ВЫРАБОТКА ПО ДНЯМ, га — последние 30 рабочих дней
A2: На 24.05.2026 · «Накоплено» — нарастающим итогом с начала сезона
C3: 46130 | D3: 46131 | E3: 46132 | F3: 46134 | G3: 46135 | H3: 46137 | I3: 46138 | J3: 46139 | K3: 46140 | L3: 46141 | M3: 46142 | N3: 46143 | O3: 46144 | P3: 46145 | Q3: 46146 | R3: 46147 | S3: 46148 | T3: 46149 | U3: 46150 | V3: 46151 | W3: 46152 | X3: 46153 | Y3: 46154 | Z3: 46155 | AA3: 46160 | AB3: 46161 | AC3: 46162 | AD3: 46164 | AE3: 46165 | AF3: 46166
A4: Вид работ | B4: Накоплено | C4: сб 18.04 | D4: вс 19.04 | E4: пн 20.04 | F4: ср 22.04 | G4: чт 23.04 | H4: сб 25.04 | I4: вс 26.04 | J4: пн 27.04 | K4: вт 28.04 | L4: ср 29.04 | M4: чт 30.04 | N4: пт 01.05 | O4: сб 02.05 | P4: вс 03.05 | Q4: пн 04.05 | R4: вт 05.05 | S4: ср 06.05 | T4: чт 07.05 | U4: пт 08.05 | V4: сб 09.05 | W4: вс 10.05 | X4: пн 11.05 | Y4: вт 12.05 | Z4: ср 13.05 | AA4: пн 18.05 | AB4: вт 19.05 | AC4: ср 20.05 | AD4: пт 22.05 | AE4: сб 23.05 | AF4: вс 24.05 | AG4: Итого за период
A5: Хим обработка | B5: =SUMIF(Выработка!$C$5:$C$254,$A5,Выработка!$F$5:$F$254) | C5: =IF(SUMIFS(Выработка!$F$5:$F$254,Выработка!$C$5:$C$254,$A5,Выработка!$A$5:$A$254,C$3)=0,"",SUMIFS(Выработка!$F$5:$F$254,Выработка!$C$5:$C$254,$A5,Выработка!$A$5:$A$254,C$3)) | D5: =IF(SUMIFS(Выработка!$F$5:$F$254,Выработка!$C$5:$C$254,$A5,Выработка!$A$5:$A$254,D$3)=0,"",SUMIFS(Выработка!$F$5:$F$254,Выработка!$C$5:$C$254,$A5,Выработка!$A$5:$A$254,D$3)) | E5: =IF(SUMIFS(Выработка!$F$5:$F$254,Выработка!$C$5:$C$254,$A5,Выработка!$A$5:$A$254,E$3)=0,"",SUMIFS(Выработка!$F$5:$F$254,Выработка!$C$5:$C$254,$A5,Выработка!$A$5:$A$254,E$3)) | F5: =IF(SUMIFS(Выработка!$F$5:$F$254,Выработка!$C$5:$C$254,$A5,Выработка!$A$5:$A$254,F$3)=0,"",SUMIFS(Выработка!$F$5:$F$254,Выработка!$C$5:$C$254,$A5,Выработка!$A$5:$A$254,F$3)) | G5: =IF(SUMIFS(Выработка!$F$5:$F$254,Выработка!$C$5:$C$254,$A5,Выработка!$A$5:$A$254,G$3)=0,"",SUMIFS(Выработка!$F$5:$F$254,Выработка!$C$5:$C$254,$A5,Выработка!$A$5:$A$254,G$3)) | H5: =IF(SUMIFS(Выработка!$F$5:$F$254,Выработка!$C$5:$C$254,$A5,Выработка!$A$5:$A$254,H$3)=0,"",SUMIFS(Выработка!$F$5:$F$254,Выработка!$C$5:$C$254,$A5,Выработка!$A$5:$A$254,H$3)) | I5: =IF(SUMIFS(Выработка!$F$5:$F$254,Выработка!$C$5:$C$254,$A5,Выработка!$A$5:$A$254,I$3)=0,"",SUMIFS(Выработка!$F$5:$F$254,Выработка!$C$5:$C$254,$A5,Выработка!$A$5:$A$254,I$3)) | J5: =IF(SUMIFS(Выработка!$F$5:$F$254,Выработка!$C$5:$C$254,$A5,Выработка!$A$5:$A$254,J$3)=0,"",SUMIFS(Выработка!$F$5:$F$254,Выработка!$C$5:$C$254,$A5,Выработка!$A$5:$A$254,J$3)) | ... AF5: =IF(SUMIFS(Выработка!$F$5:$F$254,Выработка!$C$5:$C$254,$A5,Выработка!$A$5:$A$254,AF$3)=0,"",SUMIFS(Выработка!$F$5:$F$254,Выработка!$C$5:$C$254,$A5,Выработка!$A$5:$A$254,AF$3)) | AG5: =SUM(C5:AF5)
A6: Хим обработка №2 | B6: =SUMIF(Выработка!$C$5:$C$254,$A6,Выработка!$F$5:$F$254) | C6: =IF(SUMIFS(Выработка!$F$5:$F$254,Выработка!$C$5:$C$254,$A6,Выработка!$A$5:$A$254,C$3)=0,"",SUMIFS(Выработка!$F$5:$F$254,Выработка!$C$5:$C$254,$A6,Выработка!$A$5:$A$254,C$3)) | D6: =IF(SUMIFS(Выработка!$F$5:$F$254,Выработка!$C$5:$C$254,$A6,Выработка!$A$5:$A$254,D$3)=0,"",SUMIFS(Выработка!$F$5:$F$254,Выработка!$C$5:$C$254,$A6,Выработка!$A$5:$A$254,D$3)) | E6: =IF(SUMIFS(Выработка!$F$5:$F$254,Выработка!$C$5:$C$254,$A6,Выработка!$A$5:$A$254,E$3)=0,"",SUMIFS(Выработка!$F$5:$F$254,Выработка!$C$5:$C$254,$A6,Выработка!$A$5:$A$254,E$3)) | F6: =IF(SUMIFS(Выработка!$F$5:$F$254,Выработка!$C$5:$C$254,$A6,Выработка!$A$5:$A$254,F$3)=0,"",SUMIFS(Выработка!$F$5:$F$254,Выработка!$C$5:$C$254,$A6,Выработка!$A$5:$A$254,F$3)) | G6: =IF(SUMIFS(Выработка!$F$5:$F$254,Выработка!$C$5:$C$254,$A6,Выработка!$A$5:$A$254,G$3)=0,"",SUMIFS(Выработка!$F$5:$F$254,Выработка!$C$5:$C$254,$A6,Выработка!$A$5:$A$254,G$3)) | H6: =IF(SUMIFS(Выработка!$F$5:$F$254,Выработка!$C$5:$C$254,$A6,Выработка!$A$5:$A$254,H$3)=0,"",SUMIFS(Выработка!$F$5:$F$254,Выработка!$C$5:$C$254,$A6,Выработка!$A$5:$A$254,H$3)) | I6: =IF(SUMIFS(Выработка!$F$5:$F$254,Выработка!$C$5:$C$254,$A6,Выработка!$A$5:$A$254,I$3)=0,"",SUMIFS(Выработка!$F$5:$F$254,Выработка!$C$5:$C$254,$A6,Выработка!$A$5:$A$254,I$3)) | J6: =IF(SUMIFS(Выработка!$F$5:$F$254,Выработка!$C$5:$C$254,$A6,Выработка!$A$5:$A$254,J$3)=0,"",SUMIFS(Выработка!$F$5:$F$254,Выработка!$C$5:$C$254,$A6,Выработка!$A$5:$A$254,J$3)) | ... AF6: =IF(SUMIFS(Выработка!$F$5:$F$254,Выработка!$C$5:$C$254,$A6,Выработка!$A$5:$A$254,AF$3)=0,"",SUMIFS(Выработка!$F$5:$F$254,Выработка!$C$5:$C$254,$A6,Выработка!$A$5:$A$254,AF$3)) | AG6: =SUM(C6:AF6)
A7: Внесение мин.удобрений №1 | B7: =SUMIF(Выработка!$C$5:$C$254,$A7,Выработка!$F$5:$F$254) | C7: =IF(SUMIFS(Выработка!$F$5:$F$254,Выработка!$C$5:$C$254,$A7,Выработка!$A$5:$A$254,C$3)=0,"",SUMIFS(Выработка!$F$5:$F$254,Выработка!$C$5:$C$254,$A7,Выработка!$A$5:$A$254,C$3)) | D7: =IF(SUMIFS(Выработка!$F$5:$F$254,Выработка!$C$5:$C$254,$A7,Выработка!$A$5:$A$254,D$3)=0,"",SUMIFS(Выработка!$F$5:$F$254,Выработка!$C$5:$C$254,$A7,Выработка!$A$5:$A$254,D$3)) | E7: =IF(SUMIFS(Выработка!$F$5:$F$254,Выработка!$C$5:$C$254,$A7,Выработка!$A$5:$A$254,E$3)=0,"",SUMIFS(Выработка!$F$5:$F$254,Выработка!$C$5:$C$254,$A7,Выработка!$A$5:$A$254,E$3)) | F7: =IF(SUMIFS(Выработка!$F$5:$F$254,Выработка!$C$5:$C$254,$A7,Выработка!$A$5:$A$254,F$3)=0,"",SUMIFS(Выработка!$F$5:$F$254,Выработка!$C$5:$C$254,$A7,Выработка!$A$5:$A$254,F$3)) | G7: =IF(SUMIFS(Выработка!$F$5:$F$254,Выработка!$C$5:$C$254,$A7,Выработка!$A$5:$A$254,G$3)=0,"",SUMIFS(Выработка!$F$5:$F$254,Выработка!$C$5:$C$254,$A7,Выработка!$A$5:$A$254,G$3)) | H7: =IF(SUMIFS(Выработка!$F$5:$F$254,Выработка!$C$5:$C$254,$A7,Выработка!$A$5:$A$254,H$3)=0,"",SUMIFS(Выработка!$F$5:$F$254,Выработка!$C$5:$C$254,$A7,Выработка!$A$5:$A$254,H$3)) | I7: =IF(SUMIFS(Выработка!$F$5:$F$254,Выработка!$C$5:$C$254,$A7,Выработка!$A$5:$A$254,I$3)=0,"",SUMIFS(Выработка!$F$5:$F$254,Выработка!$C$5:$C$254,$A7,Выработка!$A$5:$A$254,I$3)) | J7: =IF(SUMIFS(Выработка!$F$5:$F$254,Выработка!$C$5:$C$254,$A7,Выработка!$A$5:$A$254,J$3)=0,"",SUMIFS(Выработка!$F$5:$F$254,Выработка!$C$5:$C$254,$A7,Выработка!$A$5:$A$254,J$3)) | ... AF7: =IF(SUMIFS(Выработка!$F$5:$F$254,Выработка!$C$5:$C$254,$A7,Выработка!$A$5:$A$254,AF$3)=0,"",SUMIFS(Выработка!$F$5:$F$254,Выработка!$C$5:$C$254,$A7,Выработка!$A$5:$A$254,AF$3)) | AG7: =SUM(C7:AF7)
A8: Внесение мин.удобрений №2 | B8: =SUMIF(Выработка!$C$5:$C$254,$A8,Выработка!$F$5:$F$254) | C8: =IF(SUMIFS(Выработка!$F$5:$F$254,Выработка!$C$5:$C$254,$A8,Выработка!$A$5:$A$254,C$3)=0,"",SUMIFS(Выработка!$F$5:$F$254,Выработка!$C$5:$C$254,$A8,Выработка!$A$5:$A$254,C$3)) | D8: =IF(SUMIFS(Выработка!$F$5:$F$254,Выработка!$C$5:$C$254,$A8,Выработка!$A$5:$A$254,D$3)=0,"",SUMIFS(Выработка!$F$5:$F$254,Выработка!$C$5:$C$254,$A8,Выработка!$A$5:$A$254,D$3)) | E8: =IF(SUMIFS(Выработка!$F$5:$F$254,Выработка!$C$5:$C$254,$A8,Выработка!$A$5:$A$254,E$3)=0,"",SUMIFS(Выработка!$F$5:$F$254,Выработка!$C$5:$C$254,$A8,Выработка!$A$5:$A$254,E$3)) | F8: =IF(SUMIFS(Выработка!$F$5:$F$254,Выработка!$C$5:$C$254,$A8,Выработка!$A$5:$A$254,F$3)=0,"",SUMIFS(Выработка!$F$5:$F$254,Выработка!$C$5:$C$254,$A8,Выработка!$A$5:$A$254,F$3)) | G8: =IF(SUMIFS(Выработка!$F$5:$F$254,Выработка!$C$5:$C$254,$A8,Выработка!$A$5:$A$254,G$3)=0,"",SUMIFS(Выработка!$F$5:$F$254,Выработка!$C$5:$C$254,$A8,Выработка!$A$5:$A$254,G$3)) | H8: =IF(SUMIFS(Выработка!$F$5:$F$254,Выработка!$C$5:$C$254,$A8,Выработка!$A$5:$A$254,H$3)=0,"",SUMIFS(Выработка!$F$5:$F$254,Выработка!$C$5:$C$254,$A8,Выработка!$A$5:$A$254,H$3)) | I8: =IF(SUMIFS(Выработка!$F$5:$F$254,Выработка!$C$5:$C$254,$A8,Выработка!$A$5:$A$254,I$3)=0,"",SUMIFS(Выработка!$F$5:$F$254,Выработка!$C$5:$C$254,$A8,Выработка!$A$5:$A$254,I$3)) | J8: =IF(SUMIFS(Выработка!$F$5:$F$254,Выработка!$C$5:$C$254,$A8,Выработка!$A$5:$A$254,J$3)=0,"",SUMIFS(Выработка!$F$5:$F$254,Выработка!$C$5:$C$254,$A8,Выработка!$A$5:$A$254,J$3)) | ... AF8: =IF(SUMIFS(Выработка!$F$5:$F$254,Выработка!$C$5:$C$254,$A8,Выработка!$A$5:$A$254,AF$3)=0,"",SUMIFS(Выработка!$F$5:$F$254,Выработка!$C$5:$C$254,$A8,Выработка!$A$5:$A$254,AF$3)) | AG8: =SUM(C8:AF8)
A9: Предпосевная культивация | B9: =SUMIF(Выработка!$C$5:$C$254,$A9,Выработка!$F$5:$F$254) | C9: =IF(SUMIFS(Выработка!$F$5:$F$254,Выработка!$C$5:$C$254,$A9,Выработка!$A$5:$A$254,C$3)=0,"",SUMIFS(Выработка!$F$5:$F$254,Выработка!$C$5:$C$254,$A9,Выработка!$A$5:$A$254,C$3)) | D9: =IF(SUMIFS(Выработка!$F$5:$F$254,Выработка!$C$5:$C$254,$A9,Выработка!$A$5:$A$254,D$3)=0,"",SUMIFS(Выработка!$F$5:$F$254,Выработка!$C$5:$C$254,$A9,Выработка!$A$5:$A$254,D$3)) | E9: =IF(SUMIFS(Выработка!$F$5:$F$254,Выработка!$C$5:$C$254,$A9,Выработка!$A$5:$A$254,E$3)=0,"",SUMIFS(Выработка!$F$5:$F$254,Выработка!$C$5:$C$254,$A9,Выработка!$A$5:$A$254,E$3)) | F9: =IF(SUMIFS(Выработка!$F$5:$F$254,Выработка!$C$5:$C$254,$A9,Выработка!$A$5:$A$254,F$3)=0,"",SUMIFS(Выработка!$F$5:$F$254,Выработка!$C$5:$C$254,$A9,Выработка!$A$5:$A$254,F$3)) | G9: =IF(SUMIFS(Выработка!$F$5:$F$254,Выработка!$C$5:$C$254,$A9,Выработка!$A$5:$A$254,G$3)=0,"",SUMIFS(Выработка!$F$5:$F$254,Выработка!$C$5:$C$254,$A9,Выработка!$A$5:$A$254,G$3)) | H9: =IF(SUMIFS(Выработка!$F$5:$F$254,Выработка!$C$5:$C$254,$A9,Выработка!$A$5:$A$254,H$3)=0,"",SUMIFS(Выработка!$F$5:$F$254,Выработка!$C$5:$C$254,$A9,Выработка!$A$5:$A$254,H$3)) | I9: =IF(SUMIFS(Выработка!$F$5:$F$254,Выработка!$C$5:$C$254,$A9,Выработка!$A$5:$A$254,I$3)=0,"",SUMIFS(Выработка!$F$5:$F$254,Выработка!$C$5:$C$254,$A9,Выработка!$A$5:$A$254,I$3)) | J9: =IF(SUMIFS(Выработка!$F$5:$F$254,Выработка!$C$5:$C$254,$A9,Выработка!$A$5:$A$254,J$3)=0,"",SUMIFS(Выработка!$F$5:$F$254,Выработка!$C$5:$C$254,$A9,Выработка!$A$5:$A$254,J$3)) | ... AF9: =IF(SUMIFS(Выработка!$F$5:$F$254,Выработка!$C$5:$C$254,$A9,Выработка!$A$5:$A$254,AF$3)=0,"",SUMIFS(Выработка!$F$5:$F$254,Выработка!$C$5:$C$254,$A9,Выработка!$A$5:$A$254,AF$3)) | AG9: =SUM(C9:AF9)
A10: Сев горошка | B10: =SUMIF(Выработка!$C$5:$C$254,$A10,Выработка!$F$5:$F$254) | C10: =IF(SUMIFS(Выработка!$F$5:$F$254,Выработка!$C$5:$C$254,$A10,Выработка!$A$5:$A$254,C$3)=0,"",SUMIFS(Выработка!$F$5:$F$254,Выработка!$C$5:$C$254,$A10,Выработка!$A$5:$A$254,C$3)) | D10: =IF(SUMIFS(Выработка!$F$5:$F$254,Выработка!$C$5:$C$254,$A10,Выработка!$A$5:$A$254,D$3)=0,"",SUMIFS(Выработка!$F$5:$F$254,Выработка!$C$5:$C$254,$A10,Выработка!$A$5:$A$254,D$3)) | E10: =IF(SUMIFS(Выработка!$F$5:$F$254,Выработка!$C$5:$C$254,$A10,Выработка!$A$5:$A$254,E$3)=0,"",SUMIFS(Выработка!$F$5:$F$254,Выработка!$C$5:$C$254,$A10,Выработка!$A$5:$A$254,E$3)) | F10: =IF(SUMIFS(Выработка!$F$5:$F$254,Выработка!$C$5:$C$254,$A10,Выработка!$A$5:$A$254,F$3)=0,"",SUMIFS(Выработка!$F$5:$F$254,Выработка!$C$5:$C$254,$A10,Выработка!$A$5:$A$254,F$3)) | G10: =IF(SUMIFS(Выработка!$F$5:$F$254,Выработка!$C$5:$C$254,$A10,Выработка!$A$5:$A$254,G$3)=0,"",SUMIFS(Выработка!$F$5:$F$254,Выработка!$C$5:$C$254,$A10,Выработка!$A$5:$A$254,G$3)) | H10: =IF(SUMIFS(Выработка!$F$5:$F$254,Выработка!$C$5:$C$254,$A10,Выработка!$A$5:$A$254,H$3)=0,"",SUMIFS(Выработка!$F$5:$F$254,Выработка!$C$5:$C$254,$A10,Выработка!$A$5:$A$254,H$3)) | I10: =IF(SUMIFS(Выработка!$F$5:$F$254,Выработка!$C$5:$C$254,$A10,Выработка!$A$5:$A$254,I$3)=0,"",SUMIFS(Выработка!$F$5:$F$254,Выработка!$C$5:$C$254,$A10,Выработка!$A$5:$A$254,I$3)) | J10: =IF(SUMIFS(Выработка!$F$5:$F$254,Выработка!$C$5:$C$254,$A10,Выработка!$A$5:$A$254,J$3)=0,"",SUMIFS(Выработка!$F$5:$F$254,Выработка!$C$5:$C$254,$A10,Выработка!$A$5:$A$254,J$3)) | ... AF10: =IF(SUMIFS(Выработка!$F$5:$F$254,Выработка!$C$5:$C$254,$A10,Выработка!$A$5:$A$254,AF$3)=0,"",SUMIFS(Выработка!$F$5:$F$254,Выработка!$C$5:$C$254,$A10,Выработка!$A$5:$A$254,AF$3)) | AG10: =SUM(C10:AF10)
A11: Сев зерновых | B11: =SUMIF(Выработка!$C$5:$C$254,$A11,Выработка!$F$5:$F$254) | C11: =IF(SUMIFS(Выработка!$F$5:$F$254,Выработка!$C$5:$C$254,$A11,Выработка!$A$5:$A$254,C$3)=0,"",SUMIFS(Выработка!$F$5:$F$254,Выработка!$C$5:$C$254,$A11,Выработка!$A$5:$A$254,C$3)) | D11: =IF(SUMIFS(Выработка!$F$5:$F$254,Выработка!$C$5:$C$254,$A11,Выработка!$A$5:$A$254,D$3)=0,"",SUMIFS(Выработка!$F$5:$F$254,Выработка!$C$5:$C$254,$A11,Выработка!$A$5:$A$254,D$3)) | E11: =IF(SUMIFS(Выработка!$F$5:$F$254,Выработка!$C$5:$C$254,$A11,Выработка!$A$5:$A$254,E$3)=0,"",SUMIFS(Выработка!$F$5:$F$254,Выработка!$C$5:$C$254,$A11,Выработка!$A$5:$A$254,E$3)) | F11: =IF(SUMIFS(Выработка!$F$5:$F$254,Выработка!$C$5:$C$254,$A11,Выработка!$A$5:$A$254,F$3)=0,"",SUMIFS(Выработка!$F$5:$F$254,Выработка!$C$5:$C$254,$A11,Выработка!$A$5:$A$254,F$3)) | G11: =IF(SUMIFS(Выработка!$F$5:$F$254,Выработка!$C$5:$C$254,$A11,Выработка!$A$5:$A$254,G$3)=0,"",SUMIFS(Выработка!$F$5:$F$254,Выработка!$C$5:$C$254,$A11,Выработка!$A$5:$A$254,G$3)) | H11: =IF(SUMIFS(Выработка!$F$5:$F$254,Выработка!$C$5:$C$254,$A11,Выработка!$A$5:$A$254,H$3)=0,"",SUMIFS(Выработка!$F$5:$F$254,Выработка!$C$5:$C$254,$A11,Выработка!$A$5:$A$254,H$3)) | I11: =IF(SUMIFS(Выработка!$F$5:$F$254,Выработка!$C$5:$C$254,$A11,Выработка!$A$5:$A$254,I$3)=0,"",SUMIFS(Выработка!$F$5:$F$254,Выработка!$C$5:$C$254,$A11,Выработка!$A$5:$A$254,I$3)) | J11: =IF(SUMIFS(Выработка!$F$5:$F$254,Выработка!$C$5:$C$254,$A11,Выработка!$A$5:$A$254,J$3)=0,"",SUMIFS(Выработка!$F$5:$F$254,Выработка!$C$5:$C$254,$A11,Выработка!$A$5:$A$254,J$3)) | ... AF11: =IF(SUMIFS(Выработка!$F$5:$F$254,Выработка!$C$5:$C$254,$A11,Выработка!$A$5:$A$254,AF$3)=0,"",SUMIFS(Выработка!$F$5:$F$254,Выработка!$C$5:$C$254,$A11,Выработка!$A$5:$A$254,AF$3)) | AG11: =SUM(C11:AF11)
A12: Культивация№1 | B12: =SUMIF(Выработка!$C$5:$C$254,$A12,Выработка!$F$5:$F$254) | C12: =IF(SUMIFS(Выработка!$F$5:$F$254,Выработка!$C$5:$C$254,$A12,Выработка!$A$5:$A$254,C$3)=0,"",SUMIFS(Выработка!$F$5:$F$254,Выработка!$C$5:$C$254,$A12,Выработка!$A$5:$A$254,C$3)) | D12: =IF(SUMIFS(Выработка!$F$5:$F$254,Выработка!$C$5:$C$254,$A12,Выработка!$A$5:$A$254,D$3)=0,"",SUMIFS(Выработка!$F$5:$F$254,Выработка!$C$5:$C$254,$A12,Выработка!$A$5:$A$254,D$3)) | E12: =IF(SUMIFS(Выработка!$F$5:$F$254,Выработка!$C$5:$C$254,$A12,Выработка!$A$5:$A$254,E$3)=0,"",SUMIFS(Выработка!$F$5:$F$254,Выработка!$C$5:$C$254,$A12,Выработка!$A$5:$A$254,E$3)) | F12: =IF(SUMIFS(Выработка!$F$5:$F$254,Выработка!$C$5:$C$254,$A12,Выработка!$A$5:$A$254,F$3)=0,"",SUMIFS(Выработка!$F$5:$F$254,Выработка!$C$5:$C$254,$A12,Выработка!$A$5:$A$254,F$3)) | G12: =IF(SUMIFS(Выработка!$F$5:$F$254,Выработка!$C$5:$C$254,$A12,Выработка!$A$5:$A$254,G$3)=0,"",SUMIFS(Выработка!$F$5:$F$254,Выработка!$C$5:$C$254,$A12,Выработка!$A$5:$A$254,G$3)) | H12: =IF(SUMIFS(Выработка!$F$5:$F$254,Выработка!$C$5:$C$254,$A12,Выработка!$A$5:$A$254,H$3)=0,"",SUMIFS(Выработка!$F$5:$F$254,Выработка!$C$5:$C$254,$A12,Выработка!$A$5:$A$254,H$3)) | I12: =IF(SUMIFS(Выработка!$F$5:$F$254,Выработка!$C$5:$C$254,$A12,Выработка!$A$5:$A$254,I$3)=0,"",SUMIFS(Выработка!$F$5:$F$254,Выработка!$C$5:$C$254,$A12,Выработка!$A$5:$A$254,I$3)) | J12: =IF(SUMIFS(Выработка!$F$5:$F$254,Выработка!$C$5:$C$254,$A12,Выработка!$A$5:$A$254,J$3)=0,"",SUMIFS(Выработка!$F$5:$F$254,Выработка!$C$5:$C$254,$A12,Выработка!$A$5:$A$254,J$3)) | ... AF12: =IF(SUMIFS(Выработка!$F$5:$F$254,Выработка!$C$5:$C$254,$A12,Выработка!$A$5:$A$254,AF$3)=0,"",SUMIFS(Выработка!$F$5:$F$254,Выработка!$C$5:$C$254,$A12,Выработка!$A$5:$A$254,AF$3)) | AG12: =SUM(C12:AF12)
A13: Культивация№111 | B13: =SUMIF(Выработка!$C$5:$C$254,$A13,Выработка!$F$5:$F$254) | C13: =IF(SUMIFS(Выработка!$F$5:$F$254,Выработка!$C$5:$C$254,$A13,Выработка!$A$5:$A$254,C$3)=0,"",SUMIFS(Выработка!$F$5:$F$254,Выработка!$C$5:$C$254,$A13,Выработка!$A$5:$A$254,C$3)) | D13: =IF(SUMIFS(Выработка!$F$5:$F$254,Выработка!$C$5:$C$254,$A13,Выработка!$A$5:$A$254,D$3)=0,"",SUMIFS(Выработка!$F$5:$F$254,Выработка!$C$5:$C$254,$A13,Выработка!$A$5:$A$254,D$3)) | E13: =IF(SUMIFS(Выработка!$F$5:$F$254,Выработка!$C$5:$C$254,$A13,Выработка!$A$5:$A$254,E$3)=0,"",SUMIFS(Выработка!$F$5:$F$254,Выработка!$C$5:$C$254,$A13,Выработка!$A$5:$A$254,E$3)) | F13: =IF(SUMIFS(Выработка!$F$5:$F$254,Выработка!$C$5:$C$254,$A13,Выработка!$A$5:$A$254,F$3)=0,"",SUMIFS(Выработка!$F$5:$F$254,Выработка!$C$5:$C$254,$A13,Выработка!$A$5:$A$254,F$3)) | G13: =IF(SUMIFS(Выработка!$F$5:$F$254,Выработка!$C$5:$C$254,$A13,Выработка!$A$5:$A$254,G$3)=0,"",SUMIFS(Выработка!$F$5:$F$254,Выработка!$C$5:$C$254,$A13,Выработка!$A$5:$A$254,G$3)) | H13: =IF(SUMIFS(Выработка!$F$5:$F$254,Выработка!$C$5:$C$254,$A13,Выработка!$A$5:$A$254,H$3)=0,"",SUMIFS(Выработка!$F$5:$F$254,Выработка!$C$5:$C$254,$A13,Выработка!$A$5:$A$254,H$3)) | I13: =IF(SUMIFS(Выработка!$F$5:$F$254,Выработка!$C$5:$C$254,$A13,Выработка!$A$5:$A$254,I$3)=0,"",SUMIFS(Выработка!$F$5:$F$254,Выработка!$C$5:$C$254,$A13,Выработка!$A$5:$A$254,I$3)) | J13: =IF(SUMIFS(Выработка!$F$5:$F$254,Выработка!$C$5:$C$254,$A13,Выработка!$A$5:$A$254,J$3)=0,"",SUMIFS(Выработка!$F$5:$F$254,Выработка!$C$5:$C$254,$A13,Выработка!$A$5:$A$254,J$3)) | ... AF13: =IF(SUMIFS(Выработка!$F$5:$F$254,Выработка!$C$5:$C$254,$A13,Выработка!$A$5:$A$254,AF$3)=0,"",SUMIFS(Выработка!$F$5:$F$254,Выработка!$C$5:$C$254,$A13,Выработка!$A$5:$A$254,AF$3)) | AG13: =SUM(C13:AF13)
A14: СЕВ СЛАДКОЙ КУКУРУЗЫ | B14: =SUMIF(Выработка!$C$5:$C$254,$A14,Выработка!$F$5:$F$254) | C14: =IF(SUMIFS(Выработка!$F$5:$F$254,Выработка!$C$5:$C$254,$A14,Выработка!$A$5:$A$254,C$3)=0,"",SUMIFS(Выработка!$F$5:$F$254,Выработка!$C$5:$C$254,$A14,Выработка!$A$5:$A$254,C$3)) | D14: =IF(SUMIFS(Выработка!$F$5:$F$254,Выработка!$C$5:$C$254,$A14,Выработка!$A$5:$A$254,D$3)=0,"",SUMIFS(Выработка!$F$5:$F$254,Выработка!$C$5:$C$254,$A14,Выработка!$A$5:$A$254,D$3)) | E14: =IF(SUMIFS(Выработка!$F$5:$F$254,Выработка!$C$5:$C$254,$A14,Выработка!$A$5:$A$254,E$3)=0,"",SUMIFS(Выработка!$F$5:$F$254,Выработка!$C$5:$C$254,$A14,Выработка!$A$5:$A$254,E$3)) | F14: =IF(SUMIFS(Выработка!$F$5:$F$254,Выработка!$C$5:$C$254,$A14,Выработка!$A$5:$A$254,F$3)=0,"",SUMIFS(Выработка!$F$5:$F$254,Выработка!$C$5:$C$254,$A14,Выработка!$A$5:$A$254,F$3)) | G14: =IF(SUMIFS(Выработка!$F$5:$F$254,Выработка!$C$5:$C$254,$A14,Выработка!$A$5:$A$254,G$3)=0,"",SUMIFS(Выработка!$F$5:$F$254,Выработка!$C$5:$C$254,$A14,Выработка!$A$5:$A$254,G$3)) | H14: =IF(SUMIFS(Выработка!$F$5:$F$254,Выработка!$C$5:$C$254,$A14,Выработка!$A$5:$A$254,H$3)=0,"",SUMIFS(Выработка!$F$5:$F$254,Выработка!$C$5:$C$254,$A14,Выработка!$A$5:$A$254,H$3)) | I14: =IF(SUMIFS(Выработка!$F$5:$F$254,Выработка!$C$5:$C$254,$A14,Выработка!$A$5:$A$254,I$3)=0,"",SUMIFS(Выработка!$F$5:$F$254,Выработка!$C$5:$C$254,$A14,Выработка!$A$5:$A$254,I$3)) | J14: =IF(SUMIFS(Выработка!$F$5:$F$254,Выработка!$C$5:$C$254,$A14,Выработка!$A$5:$A$254,J$3)=0,"",SUMIFS(Выработка!$F$5:$F$254,Выработка!$C$5:$C$254,$A14,Выработка!$A$5:$A$254,J$3)) | ... AF14: =IF(SUMIFS(Выработка!$F$5:$F$254,Выработка!$C$5:$C$254,$A14,Выработка!$A$5:$A$254,AF$3)=0,"",SUMIFS(Выработка!$F$5:$F$254,Выработка!$C$5:$C$254,$A14,Выработка!$A$5:$A$254,AF$3)) | AG14: =SUM(C14:AF14)
A15: Прикатывание до всходов | B15: =SUMIF(Выработка!$C$5:$C$254,$A15,Выработка!$F$5:$F$254) | C15: =IF(SUMIFS(Выработка!$F$5:$F$254,Выработка!$C$5:$C$254,$A15,Выработка!$A$5:$A$254,C$3)=0,"",SUMIFS(Выработка!$F$5:$F$254,Выработка!$C$5:$C$254,$A15,Выработка!$A$5:$A$254,C$3)) | D15: =IF(SUMIFS(Выработка!$F$5:$F$254,Выработка!$C$5:$C$254,$A15,Выработка!$A$5:$A$254,D$3)=0,"",SUMIFS(Выработка!$F$5:$F$254,Выработка!$C$5:$C$254,$A15,Выработка!$A$5:$A$254,D$3)) | E15: =IF(SUMIFS(Выработка!$F$5:$F$254,Выработка!$C$5:$C$254,$A15,Выработка!$A$5:$A$254,E$3)=0,"",SUMIFS(Выработка!$F$5:$F$254,Выработка!$C$5:$C$254,$A15,Выработка!$A$5:$A$254,E$3)) | F15: =IF(SUMIFS(Выработка!$F$5:$F$254,Выработка!$C$5:$C$254,$A15,Выработка!$A$5:$A$254,F$3)=0,"",SUMIFS(Выработка!$F$5:$F$254,Выработка!$C$5:$C$254,$A15,Выработка!$A$5:$A$254,F$3)) | G15: =IF(SUMIFS(Выработка!$F$5:$F$254,Выработка!$C$5:$C$254,$A15,Выработка!$A$5:$A$254,G$3)=0,"",SUMIFS(Выработка!$F$5:$F$254,Выработка!$C$5:$C$254,$A15,Выработка!$A$5:$A$254,G$3)) | H15: =IF(SUMIFS(Выработка!$F$5:$F$254,Выработка!$C$5:$C$254,$A15,Выработка!$A$5:$A$254,H$3)=0,"",SUMIFS(Выработка!$F$5:$F$254,Выработка!$C$5:$C$254,$A15,Выработка!$A$5:$A$254,H$3)) | I15: =IF(SUMIFS(Выработка!$F$5:$F$254,Выработка!$C$5:$C$254,$A15,Выработка!$A$5:$A$254,I$3)=0,"",SUMIFS(Выработка!$F$5:$F$254,Выработка!$C$5:$C$254,$A15,Выработка!$A$5:$A$254,I$3)) | J15: =IF(SUMIFS(Выработка!$F$5:$F$254,Выработка!$C$5:$C$254,$A15,Выработка!$A$5:$A$254,J$3)=0,"",SUMIFS(Выработка!$F$5:$F$254,Выработка!$C$5:$C$254,$A15,Выработка!$A$5:$A$254,J$3)) | ... AF15: =IF(SUMIFS(Выработка!$F$5:$F$254,Выработка!$C$5:$C$254,$A15,Выработка!$A$5:$A$254,AF$3)=0,"",SUMIFS(Выработка!$F$5:$F$254,Выработка!$C$5:$C$254,$A15,Выработка!$A$5:$A$254,AF$3)) | AG15: =SUM(C15:AF15)
A16: Культивация№2 | B16: =SUMIF(Выработка!$C$5:$C$254,$A16,Выработка!$F$5:$F$254) | C16: =IF(SUMIFS(Выработка!$F$5:$F$254,Выработка!$C$5:$C$254,$A16,Выработка!$A$5:$A$254,C$3)=0,"",SUMIFS(Выработка!$F$5:$F$254,Выработка!$C$5:$C$254,$A16,Выработка!$A$5:$A$254,C$3)) | D16: =IF(SUMIFS(Выработка!$F$5:$F$254,Выработка!$C$5:$C$254,$A16,Выработка!$A$5:$A$254,D$3)=0,"",SUMIFS(Выработка!$F$5:$F$254,Выработка!$C$5:$C$254,$A16,Выработка!$A$5:$A$254,D$3)) | E16: =IF(SUMIFS(Выработка!$F$5:$F$254,Выработка!$C$5:$C$254,$A16,Выработка!$A$5:$A$254,E$3)=0,"",SUMIFS(Выработка!$F$5:$F$254,Выработка!$C$5:$C$254,$A16,Выработка!$A$5:$A$254,E$3)) | F16: =IF(SUMIFS(Выработка!$F$5:$F$254,Выработка!$C$5:$C$254,$A16,Выработка!$A$5:$A$254,F$3)=0,"",SUMIFS(Выработка!$F$5:$F$254,Выработка!$C$5:$C$254,$A16,Выработка!$A$5:$A$254,F$3)) | G16: =IF(SUMIFS(Выработка!$F$5:$F$254,Выработка!$C$5:$C$254,$A16,Выработка!$A$5:$A$254,G$3)=0,"",SUMIFS(Выработка!$F$5:$F$254,Выработка!$C$5:$C$254,$A16,Выработка!$A$5:$A$254,G$3)) | H16: =IF(SUMIFS(Выработка!$F$5:$F$254,Выработка!$C$5:$C$254,$A16,Выработка!$A$5:$A$254,H$3)=0,"",SUMIFS(Выработка!$F$5:$F$254,Выработка!$C$5:$C$254,$A16,Выработка!$A$5:$A$254,H$3)) | I16: =IF(SUMIFS(Выработка!$F$5:$F$254,Выработка!$C$5:$C$254,$A16,Выработка!$A$5:$A$254,I$3)=0,"",SUMIFS(Выработка!$F$5:$F$254,Выработка!$C$5:$C$254,$A16,Выработка!$A$5:$A$254,I$3)) | J16: =IF(SUMIFS(Выработка!$F$5:$F$254,Выработка!$C$5:$C$254,$A16,Выработка!$A$5:$A$254,J$3)=0,"",SUMIFS(Выработка!$F$5:$F$254,Выработка!$C$5:$C$254,$A16,Выработка!$A$5:$A$254,J$3)) | ... AF16: =IF(SUMIFS(Выработка!$F$5:$F$254,Выработка!$C$5:$C$254,$A16,Выработка!$A$5:$A$254,AF$3)=0,"",SUMIFS(Выработка!$F$5:$F$254,Выработка!$C$5:$C$254,$A16,Выработка!$A$5:$A$254,AF$3)) | AG16: =SUM(C16:AF16)
... A18: Глубокое рыхление 40-45 | B18: =SUMIF(Выработка!$C$5:$C$254,$A18,Выработка!$F$5:$F$254) | C18: =IF(SUMIFS(Выработка!$F$5:$F$254,Выработка!$C$5:$C$254,$A18,Выработка!$A$5:$A$254,C$3)=0,"",SUMIFS(Выработка!$F$5:$F$254,Выработка!$C$5:$C$254,$A18,Выработка!$A$5:$A$254,C$3)) | D18: =IF(SUMIFS(Выработка!$F$5:$F$254,Выработка!$C$5:$C$254,$A18,Выработка!$A$5:$A$254,D$3)=0,"",SUMIFS(Выработка!$F$5:$F$254,Выработка!$C$5:$C$254,$A18,Выработка!$A$5:$A$254,D$3)) | E18: =IF(SUMIFS(Выработка!$F$5:$F$254,Выработка!$C$5:$C$254,$A18,Выработка!$A$5:$A$254,E$3)=0,"",SUMIFS(Выработка!$F$5:$F$254,Выработка!$C$5:$C$254,$A18,Выработка!$A$5:$A$254,E$3)) | F18: =IF(SUMIFS(Выработка!$F$5:$F$254,Выработка!$C$5:$C$254,$A18,Выработка!$A$5:$A$254,F$3)=0,"",SUMIFS(Выработка!$F$5:$F$254,Выработка!$C$5:$C$254,$A18,Выработка!$A$5:$A$254,F$3)) | G18: =IF(SUMIFS(Выработка!$F$5:$F$254,Выработка!$C$5:$C$254,$A18,Выработка!$A$5:$A$254,G$3)=0,"",SUMIFS(Выработка!$F$5:$F$254,Выработка!$C$5:$C$254,$A18,Выработка!$A$5:$A$254,G$3)) | H18: =IF(SUMIFS(Выработка!$F$5:$F$254,Выработка!$C$5:$C$254,$A18,Выработка!$A$5:$A$254,H$3)=0,"",SUMIFS(Выработка!$F$5:$F$254,Выработка!$C$5:$C$254,$A18,Выработка!$A$5:$A$254,H$3)) | I18: =IF(SUMIFS(Выработка!$F$5:$F$254,Выработка!$C$5:$C$254,$A18,Выработка!$A$5:$A$254,I$3)=0,"",SUMIFS(Выработка!$F$5:$F$254,Выработка!$C$5:$C$254,$A18,Выработка!$A$5:$A$254,I$3)) | J18: =IF(SUMIFS(Выработка!$F$5:$F$254,Выработка!$C$5:$C$254,$A18,Выработка!$A$5:$A$254,J$3)=0,"",SUMIFS(Выработка!$F$5:$F$254,Выработка!$C$5:$C$254,$A18,Выработка!$A$5:$A$254,J$3)) | ... AF18: =IF(SUMIFS(Выработка!$F$5:$F$254,Выработка!$C$5:$C$254,$A18,Выработка!$A$5:$A$254,AF$3)=0,"",SUMIFS(Выработка!$F$5:$F$254,Выработка!$C$5:$C$254,$A18,Выработка!$A$5:$A$254,AF$3)) | AG18: =SUM(C18:AF18)
A19: ИТОГО ЗА ДЕНЬ | B19: =SUM(B5:B18) | C19: =SUM(C5:C18) | D19: =SUM(D5:D18) | E19: =SUM(E5:E18) | F19: =SUM(F5:F18) | G19: =SUM(G5:G18) | H19: =SUM(H5:H18) | I19: =SUM(I5:I18) | ... AG19: =SUM(AG5:AG18)

Sheet Сроки
A1: СРОКИ ВЫПОЛНЕНИЯ РАБОТ
A2: На 24.05.2026 · положительный сдвиг = вышли в поле позже агротехнического срока
A4: Вид работ | B4: Культура | C4: Предприятие | D4: Начало ПЛАН | E4: Окончание ПЛАН | F4: Начало ФАКТ | G4: Окончание ФАКТ | H4: Сдвиг старта, дн. | I4: Выполнение | J4: Комментарий
A5: Хим обработка | B5: Пшеница озимая | C5: ГРК | F5: 46113 | G5: 46135 | H5: =IF(AND(D5<>"",F5<>""),F5-D5,"") | I5: =Данные!I5 | J5: =IF(I5>=0.995,"закрыто",IF(AND(E5<>"",E5<TODAY()),"агросрок истёк, не закрыто",IF(F5="","не начинали","в работе")))
A6: Хим обработка | B6: Пшеница озимая | C6: ГРК | F6: 46137 | G6: 46152 | H6: =IF(AND(D6<>"",F6<>""),F6-D6,"") | I6: =Данные!I6 | J6: =IF(I6>=0.995,"закрыто",IF(AND(E6<>"",E6<TODAY()),"агросрок истёк, не закрыто",IF(F6="","не начинали","в работе")))
A7: Хим обработка | B7: Пшеница озимая | C7: ГРК | F7: 46128 | G7: 46129 | H7: =IF(AND(D7<>"",F7<>""),F7-D7,"") | I7: =Данные!I7 | J7: =IF(I7>=0.995,"закрыто",IF(AND(E7<>"",E7<TODAY()),"агросрок истёк, не закрыто",IF(F7="","не начинали","в работе")))
A8: Хим обработка | B8: Подсонечниик | C8: ГРК | F8: 46117 | G8: 46130 | H8: =IF(AND(D8<>"",F8<>""),F8-D8,"") | I8: =Данные!I8 | J8: =IF(I8>=0.995,"закрыто",IF(AND(E8<>"",E8<TODAY()),"агросрок истёк, не закрыто",IF(F8="","не начинали","в работе")))
A9: Хим обработка | B9: Рапс озимый | C9: ГРК | F9: 46110 | G9: 46113 | H9: =IF(AND(D9<>"",F9<>""),F9-D9,"") | I9: =Данные!I9 | J9: =IF(I9>=0.995,"закрыто",IF(AND(E9<>"",E9<TODAY()),"агросрок истёк, не закрыто",IF(F9="","не начинали","в работе")))
A10: Хим обработка | B10: Горох овощной (богара) | C10: ГРК | F10: 46117 | H10: =IF(AND(D10<>"",F10<>""),F10-D10,"") | I10: =Данные!I10 | J10: =IF(I10>=0.995,"закрыто",IF(AND(E10<>"",E10<TODAY()),"агросрок истёк, не закрыто",IF(F10="","не начинали","в работе")))
A11: Хим обработка | B11: Горох овощной (полив) | C11: ГРК | F11: 46135 | H11: =IF(AND(D11<>"",F11<>""),F11-D11,"") | I11: =Данные!I11 | J11: =IF(I11>=0.995,"закрыто",IF(AND(E11<>"",E11<TODAY()),"агросрок истёк, не закрыто",IF(F11="","не начинали","в работе")))
A12: Хим обработка | B12: Горох овощной (полив) | C12: ГРК | F12: 46149 | H12: =IF(AND(D12<>"",F12<>""),F12-D12,"") | I12: =Данные!I12 | J12: =IF(I12>=0.995,"закрыто",IF(AND(E12<>"",E12<TODAY()),"агросрок истёк, не закрыто",IF(F12="","не начинали","в работе")))
A13: Хим обработка | B13: Подсолнечник товарный | C13: ГРК | F13: 46154 | G13: 46166 | H13: =IF(AND(D13<>"",F13<>""),F13-D13,"") | I13: =Данные!I13 | J13: =IF(I13>=0.995,"закрыто",IF(AND(E13<>"",E13<TODAY()),"агросрок истёк, не закрыто",IF(F13="","не начинали","в работе")))
A14: Хим обработка | B14: Кукуруза на зерно | C14: ГРК | F14: 46164 | G14: 46165 | H14: =IF(AND(D14<>"",F14<>""),F14-D14,"") | I14: =Данные!I14 | J14: =IF(I14>=0.995,"закрыто",IF(AND(E14<>"",E14<TODAY()),"агросрок истёк, не закрыто",IF(F14="","не начинали","в работе")))
A15: Хим обработка | B15: Горох овощной (богара) | C15: ГРК | F15: 46133 | G15: 46166 | H15: =IF(AND(D15<>"",F15<>""),F15-D15,"") | I15: =Данные!I15 | J15: =IF(I15>=0.995,"закрыто",IF(AND(E15<>"",E15<TODAY()),"агросрок истёк, не закрыто",IF(F15="","не начинали","в работе")))
A16: Хим обработка | B16: Горох овощной (полив) | C16: ГРК | F16: 46165 | H16: =IF(AND(D16<>"",F16<>""),F16-D16,"") | I16: =Данные!I16 | J16: =IF(I16>=0.995,"закрыто",IF(AND(E16<>"",E16<TODAY()),"агросрок истёк, не закрыто",IF(F16="","не начинали","в работе")))
A17: Хим обработка | B17: Кукуруза супер.сладкая(полив) | C17: ГРК | F17: 46166 | G17: 46166 | H17: =IF(AND(D17<>"",F17<>""),F17-D17,"") | I17: =Данные!I17 | J17: =IF(I17>=0.995,"закрыто",IF(AND(E17<>"",E17<TODAY()),"агросрок истёк, не закрыто",IF(F17="","не начинали","в работе")))
A18: Хим обработка №2 | B18: Рапс озимый | C18: ГРК | F18: 46113 | G18: 46114 | H18: =IF(AND(D18<>"",F18<>""),F18-D18,"") | I18: =Данные!I18 | J18: =IF(I18>=0.995,"закрыто",IF(AND(E18<>"",E18<TODAY()),"агросрок истёк, не закрыто",IF(F18="","не начинали","в работе")))
A19: Хим обработка №2 | B19: Рапс озимый | C19: ГРК | F19: 46129 | G19: 46132 | H19: =IF(AND(D19<>"",F19<>""),F19-D19,"") | I19: =Данные!I19 | J19: =IF(I19>=0.995,"закрыто",IF(AND(E19<>"",E19<TODAY()),"агросрок истёк, не закрыто",IF(F19="","не начинали","в работе")))
A20: Хим обработка №2 | B20: Пшеница озимая | C20: ГРК | F20: 46137 | H20: =IF(AND(D20<>"",F20<>""),F20-D20,"") | I20: =Данные!I20 | J20: =IF(I20>=0.995,"закрыто",IF(AND(E20<>"",E20<TODAY()),"агросрок истёк, не закрыто",IF(F20="","не начинали","в работе")))
A21: Хим обработка №2 | B21: Горох овощной (богара) | C21: ГРК | F21: 46149 | H21: =IF(AND(D21<>"",F21<>""),F21-D21,"") | I21: =Данные!I21 | J21: =IF(I21>=0.995,"закрыто",IF(AND(E21<>"",E21<TODAY()),"агросрок истёк, не закрыто",IF(F21="","не начинали","в работе")))
A22: Хим обработка №2 | B22: Горох овощной (богара) | C22: ГРК | F22: 46142 | H22: =IF(AND(D22<>"",F22<>""),F22-D22,"") | I22: =Данные!I22 | J22: =IF(I22>=0.995,"закрыто",IF(AND(E22<>"",E22<TODAY()),"агросрок истёк, не закрыто",IF(F22="","не начинали","в работе")))
A23: Хим обработка №2 | B23: Горох овощной (полив) | C23: ГРК | F23: 46164 | H23: =IF(AND(D23<>"",F23<>""),F23-D23,"") | I23: =Данные!I23 | J23: =IF(I23>=0.995,"закрыто",IF(AND(E23<>"",E23<TODAY()),"агросрок истёк, не закрыто",IF(F23="","не начинали","в работе")))
A24: Внесение мин.удобрений №1 | B24: Пшеница озимая | C24: ГРК | D24: 46080 | E24: 46084 | F24: 46080 | G24: 46084 | H24: =IF(AND(D24<>"",F24<>""),F24-D24,"") | I24: =Данные!I24 | J24: =IF(I24>=0.995,"закрыто",IF(AND(E24<>"",E24<TODAY()),"агросрок истёк, не закрыто",IF(F24="","не начинали","в работе")))
A25: Внесение мин.удобрений №1 | B25: Горох овощной (богара) | C25: ГРК | F25: 46152 | H25: =IF(AND(D25<>"",F25<>""),F25-D25,"") | I25: =Данные!I25 | J25: =IF(I25>=0.995,"закрыто",IF(AND(E25<>"",E25<TODAY()),"агросрок истёк, не закрыто",IF(F25="","не начинали","в работе")))
A26: Внесение мин.удобрений №1 | B26: Рапс озимый | C26: ГРК | D26: 46080 | E26: 46084 | F26: 46084 | G26: 46084 | H26: =IF(AND(D26<>"",F26<>""),F26-D26,"") | I26: =Данные!I26 | J26: =IF(I26>=0.995,"закрыто",IF(AND(E26<>"",E26<TODAY()),"агросрок истёк, не закрыто",IF(F26="","не начинали","в работе")))
A27: Внесение мин.удобрений №2 | B27: Рапс озимый | C27: ГРК | F27: 46111 | G27: 46111 | H27: =IF(AND(D27<>"",F27<>""),F27-D27,"") | I27: =Данные!I27 | J27: =IF(I27>=0.995,"закрыто",IF(AND(E27<>"",E27<TODAY()),"агросрок истёк, не закрыто",IF(F27="","не начинали","в работе")))
A28: Внесение мин.удобрений №2 | B28: Пшеница озимая | C28: ГРК | D28: 46104 | E28: 46110 | F28: 46104 | H28: =IF(AND(D28<>"",F28<>""),F28-D28,"") | I28: =Данные!I28 | J28: =IF(I28>=0.995,"закрыто",IF(AND(E28<>"",E28<TODAY()),"агросрок истёк, не закрыто",IF(F28="","не начинали","в работе")))
A29: Предпосевная культивация | B29: Горох овощной (полив) | C29: ГРК | D29: 46106 | E29: 46142 | F29: 46137 | H29: =IF(AND(D29<>"",F29<>""),F29-D29,"") | I29: =Данные!I29 | J29: =IF(I29>=0.995,"закрыто",IF(AND(E29<>"",E29<TODAY()),"агросрок истёк, не закрыто",IF(F29="","не начинали","в работе")))
A30: Предпосевная культивация | B30: Подсолнечник гибридный | C30: ГРК | F30: 46138 | H30: =IF(AND(D30<>"",F30<>""),F30-D30,"") | I30: =Данные!I30 | J30: =IF(I30>=0.995,"закрыто",IF(AND(E30<>"",E30<TODAY()),"агросрок истёк, не закрыто",IF(F30="","не начинали","в работе")))
A31: Предпосевная культивация | B31: Горох овощной (богара) | C31: ГРК | D31: 46026 | E31: 46101 | F31: 46085 | H31: =IF(AND(D31<>"",F31<>""),F31-D31,"") | I31: =Данные!I31 | J31: =IF(I31>=0.995,"закрыто",IF(AND(E31<>"",E31<TODAY()),"агросрок истёк, не закрыто",IF(F31="","не начинали","в работе")))
A32: Предпосевная культивация | B32: Подсолнечник | C32: ГРК | D32: 46113 | E32: 46122 | F32: 46114 | G32: 46119 | H32: =IF(AND(D32<>"",F32<>""),F32-D32,"") | I32: =Данные!I32 | J32: =IF(I32>=0.995,"закрыто",IF(AND(E32<>"",E32<TODAY()),"агросрок истёк, не закрыто",IF(F32="","не начинали","в работе")))
A33: Предпосевная культивация | B33: Кукуруза на зерно | C33: ГРК | D33: 46122 | E33: 46127 | F33: 46130 | G33: 46130 | H33: =IF(AND(D33<>"",F33<>""),F33-D33,"") | I33: =Данные!I33 | J33: =IF(I33>=0.995,"закрыто",IF(AND(E33<>"",E33<TODAY()),"агросрок истёк, не закрыто",IF(F33="","не начинали","в работе")))
A34: Предпосевная культивация | B34: кукуруза супер сладкая | C34: ГРК | F34: 46148 | H34: =IF(AND(D34<>"",F34<>""),F34-D34,"") | I34: =Данные!I34 | J34: =IF(I34>=0.995,"закрыто",IF(AND(E34<>"",E34<TODAY()),"агросрок истёк, не закрыто",IF(F34="","не начинали","в работе")))
A35: Предпосевная культивация | B35: Подсолнечник товарный | C35: ГРК | F35: 46117 | H35: =IF(AND(D35<>"",F35<>""),F35-D35,"") | I35: =Данные!I35 | J35: =IF(I35>=0.995,"закрыто",IF(AND(E35<>"",E35<TODAY()),"агросрок истёк, не закрыто",IF(F35="","не начинали","в работе")))
A36: Сев горошка | B36: Горох овощной (богара) | C36: ГРК | D36: 46082 | E36: 46116 | F36: 46082 | G36: 46146 | H36: =IF(AND(D36<>"",F36<>""),F36-D36,"") | I36: =Данные!I36 | J36: =IF(I36>=0.995,"закрыто",IF(AND(E36<>"",E36<TODAY()),"агросрок истёк, не закрыто",IF(F36="","не начинали","в работе")))
A37: Сев горошка | B37: Горох овощной (полив) | C37: ГРК | D37: 46111 | E37: 46147 | F37: 46113 | G37: 46148 | H37: =IF(AND(D37<>"",F37<>""),F37-D37,"") | I37: =Данные!I37 | J37: =IF(I37>=0.995,"закрыто",IF(AND(E37<>"",E37<TODAY()),"агросрок истёк, не закрыто",IF(F37="","не начинали","в работе")))
A38: Сев горошка | B38: Горох овощной (полив) | C38: АгроЛидер | D38: 46117 | E38: 46124 | F38: 46117 | G38: 46128 | H38: =IF(AND(D38<>"",F38<>""),F38-D38,"") | I38: =Данные!I38 | J38: =IF(I38>=0.995,"закрыто",IF(AND(E38<>"",E38<TODAY()),"агросрок истёк, не закрыто",IF(F38="","не начинали","в работе")))
A39: Сев горошка | B39: Горох овощной (полив) | C39: Колос | D39: 46125 | E39: 46138 | F39: 46129 | G39: 46141 | H39: =IF(AND(D39<>"",F39<>""),F39-D39,"") | I39: =Данные!I39 | J39: =IF(I39>=0.995,"закрыто",IF(AND(E39<>"",E39<TODAY()),"агросрок истёк, не закрыто",IF(F39="","не начинали","в работе")))
A40: Сев зерновых | B40: Подсолнечник товарный | C40: ГРК | F40: 46117 | G40: 46131 | H40: =IF(AND(D40<>"",F40<>""),F40-D40,"") | I40: =Данные!I40 | J40: =IF(I40>=0.995,"закрыто",IF(AND(E40<>"",E40<TODAY()),"агросрок истёк, не закрыто",IF(F40="","не начинали","в работе")))
A41: Сев зерновых | B41: Кукуруза на зерно | C41: ГРК | F41: 46130 | G41: 46132 | H41: =IF(AND(D41<>"",F41<>""),F41-D41,"") | I41: =Данные!I41 | J41: =IF(I41>=0.995,"закрыто",IF(AND(E41<>"",E41<TODAY()),"агросрок истёк, не закрыто",IF(F41="","не начинали","в работе")))
...

Sheet Данные
A1: ДАННЫЕ — плоская выгрузка «Общего свода»
A2: Значения выгружены из свода. Столбцы H и I — формулы; остальное менять только в своде.
A4: Раздел | B4: Вид работ | C4: Подоперация | D4: Культура | E4: Предприятие | F4: План, га | G4: Факт, га | H4: Остаток, га | I4: Выполнение, % | J4: Начало ПЛАН | K4: Окончание ПЛАН | L4: Начало ФАКТ | M4: Окончание ФАКТ | N4: Строка свода
A5: ВЕСЕННЕ-ПОЛЕВЫЕ РАБОТЫ | B5: Хим обработка | C5: гербицидная | D5: Пшеница озимая | E5: ГРК | F5: 3798 | G5: 3776 | H5: =F5-G5 | I5: =IFERROR(G5/F5,"") | L5: 46113 | M5: 46135 | N5: 25
A6: ВЕСЕННЕ-ПОЛЕВЫЕ РАБОТЫ | B6: Хим обработка | C6: фунгицидная (1 раз) | D6: Пшеница озимая | E6: ГРК | F6: 3798 | G6: 3724 | H6: =F6-G6 | I6: =IFERROR(G6/F6,"") | L6: 46137 | M6: 46152 | N6: 26
A7: ВЕСЕННЕ-ПОЛЕВЫЕ РАБОТЫ | B7: Хим обработка | C7: Противозлаковая | D7: Пшеница озимая | E7: ГРК | F7: 239 | G7: 239 | H7: =F7-G7 | I7: =IFERROR(G7/F7,"") | L7: 46128 | M7: 46129 | N7: 27
A8: ВЕСЕННЕ-ПОЛЕВЫЕ РАБОТЫ | B8: Хим обработка | C8: глифосатная | D8: Подсонечниик | E8: ГРК | F8: 461 | G8: 363 | H8: =F8-G8 | I8: =IFERROR(G8/F8,"") | L8: 46117 | M8: 46130 | N8: 28
A9: ВЕСЕННЕ-ПОЛЕВЫЕ РАБОТЫ | B9: Хим обработка | D9: Рапс озимый | E9: ГРК | F9: 251 | G9: 251 | H9: =F9-G9 | I9: =IFERROR(G9/F9,"") | L9: 46110 | M9: 46113 | N9: 29
A10: ВЕСЕННЕ-ПОЛЕВЫЕ РАБОТЫ | B10: Хим обработка | C10: довсходовая глифосатная | D10: Горох овощной (богара) | E10: ГРК | F10: 778 | G10: 191 | H10: =F10-G10 | I10: =IFERROR(G10/F10,"") | L10: 46117 | N10: 30
A11: ВЕСЕННЕ-ПОЛЕВЫЕ РАБОТЫ | B11: Хим обработка | C11: По всходам гербицидом | D11: Горох овощной (полив) | E11: ГРК | F11: 420 | G11: 366 | H11: =F11-G11 | I11: =IFERROR(G11/F11,"") | L11: 46135 | N11: 31
A12: ВЕСЕННЕ-ПОЛЕВЫЕ РАБОТЫ | B12: Хим обработка | C12: фунгицидная (1 раз) | D12: Горох овощной (полив) | E12: ГРК | F12: 420 | G12: 153 | H12: =F12-G12 | I12: =IFERROR(G12/F12,"") | L12: 46149 | N12: 32
A13: ВЕСЕННЕ-ПОЛЕВЫЕ РАБОТЫ | B13: Хим обработка | C13: гербицидная | D13: Подсолнечник товарный | E13: ГРК | F13: 910 | G13: 910 | H13: =F13-G13 | I13: =IFERROR(G13/F13,"") | L13: 46154 | M13: 46166 | N13: 33
A14: ВЕСЕННЕ-ПОЛЕВЫЕ РАБОТЫ | B14: Хим обработка | C14: гербицидная | D14: Кукуруза на зерно | E14: ГРК | F14: 237 | G14: 237 | H14: =F14-G14 | I14: =IFERROR(G14/F14,"") | L14: 46164 | M14: 46165 | N14: 34
A15: ВЕСЕННЕ-ПОЛЕВЫЕ РАБОТЫ | B15: Хим обработка | C15: фунгицидная (1 раз) | D15: Горох овощной (богара) | E15: ГРК | F15: 778 | G15: 778 | H15: =F15-G15 | I15: =IFERROR(G15/F15,"") | L15: 46133 | M15: 46166 | N15: 35
A16: ВЕСЕННЕ-ПОЛЕВЫЕ РАБОТЫ | B16: Хим обработка | C16: Листовая | D16: Горох овощной (полив) | E16: ГРК | F16: 420 | G16: 93 | H16: =F16-G16 | I16: =IFERROR(G16/F16,"") | L16: 46165 | N16: 36
A17: ВЕСЕННЕ-ПОЛЕВЫЕ РАБОТЫ | B17: Хим обработка | C17: Гербицидная | D17: Кукуруза супер.сладкая(полив) | E17: ГРК | F17: 117 | G17: 117 | H17: =F17-G17 | I17: =IFERROR(G17/F17,"") | L17: 46166 | M17: 46166 | N17: 37
A18: ВЕСЕННЕ-ПОЛЕВЫЕ РАБОТЫ | B18: Хим обработка №2 | C18: инсектицидная-фунгицидная (1 раз) | D18: Рапс озимый | E18: ГРК | F18: 251 | G18: 251 | H18: =F18-G18 | I18: =IFERROR(G18/F18,"") | L18: 46113 | M18: 46114 | N18: 39
A19: ВЕСЕННЕ-ПОЛЕВЫЕ РАБОТЫ | B19: Хим обработка №2 | C19: инсектицидная-фунгицидная (2 раз) | D19: Рапс озимый | E19: ГРК | F19: 251 | G19: 251 | H19: =F19-G19 | I19: =IFERROR(G19/F19,"") | L19: 46129 | M19: 46132 | N19: 40
A20: ВЕСЕННЕ-ПОЛЕВЫЕ РАБОТЫ | B20: Хим обработка №2 | C20: инскктицидно-фунгицидная | D20: Пшеница озимая | E20: ГРК | F20: 3798 | G20: 2433 | H20: =F20-G20 | I20: =IFERROR(G20/F20,"") | L20: 46137 | N20: 41
A21: ВЕСЕННЕ-ПОЛЕВЫЕ РАБОТЫ | B21: Хим обработка №2 | C21: По всходам гербицидом (2 раз) | D21: Горох овощной (богара) | E21: ГРК | F21: 778 | G21: 108 | H21: =F21-G21 | I21: =IFERROR(G21/F21,"") | L21: 46149 | N21: 42
A22: ВЕСЕННЕ-ПОЛЕВЫЕ РАБОТЫ | B22: Хим обработка №2 | C22: фунгицидная (2 раз) | D22: Горох овощной (богара) | E22: ГРК | F22: 778 | G22: 657 | H22: =F22-G22 | I22: =IFERROR(G22/F22,"") | L22: 46142 | N22: 43
A23: ВЕСЕННЕ-ПОЛЕВЫЕ РАБОТЫ | B23: Хим обработка №2 | C23: фунгицидная (2 раз) | D23: Горох овощной (полив) | E23: ГРК | F23: 420 | G23: 20 | H23: =F23-G23 | I23: =IFERROR(G23/F23,"") | L23: 46164 | N23: 44
A24: ВЕСЕННЕ-ПОЛЕВЫЕ РАБОТЫ | B24: Внесение мин.удобрений №1 | C24: Селитра аммиачная | D24: Пшеница озимая | E24: ГРК | F24: 3798 | G24: 3798 | H24: =F24-G24 | I24: =IFERROR(G24/F24,"") | J24: 46080 | K24: 46084 | L24: 46080 | M24: 46084 | N24: 18
A25: ВЕСЕННЕ-ПОЛЕВЫЕ РАБОТЫ | B25: Внесение мин.удобрений №1 | C25: Листовая | D25: Горох овощной (богара) | E25: ГРК | F25: 778 | G25: 289 | H25: =F25-G25 | I25: =IFERROR(G25/F25,"") | L25: 46152 | N25: 19
A26: ВЕСЕННЕ-ПОЛЕВЫЕ РАБОТЫ | B26: Внесение мин.удобрений №1 | C26: Селитра аммиачная | D26: Рапс озимый | E26: ГРК | F26: 251 | G26: 251 | H26: =F26-G26 | I26: =IFERROR(G26/F26,"") | J26: 46080 | K26: 46084 | L26: 46084 | M26: 46084 | N26: 20
A27: ВЕСЕННЕ-ПОЛЕВЫЕ РАБОТЫ | B27: Внесение мин.удобрений №2 | C27: Селитра аммиачная | D27: Рапс озимый | E27: ГРК | F27: 251 | G27: 251 | H27: =F27-G27 | I27: =IFERROR(G27/F27,"") | L27: 46111 | M27: 46111 | N27: 22
A28: ВЕСЕННЕ-ПОЛЕВЫЕ РАБОТЫ | B28: Внесение мин.удобрений №2 | C28: Селитра аммиачная | D28: Пшеница озимая | E28: ГРК | F28: 3798 | G28: 3798 | H28: =F28-G28 | I28: =IFERROR(G28/F28,"") | J28: 46104 | K28: 46110 | L28: 46104 | N28: 23
A29: ВЕСЕННЕ-ПОЛЕВЫЕ РАБОТЫ | B29: Предпосевная культивация | D29: Горох овощной (полив) | E29: ГРК | F29: 420 | G29: 307 | H29: =F29-G29 | I29: =IFERROR(G29/F29,"") | J29: 46106 | K29: 46142 | L29: 46137 | N29: 63
A30: ВЕСЕННЕ-ПОЛЕВЫЕ РАБОТЫ | B30: Предпосевная культивация | D30: Подсолнечник гибридный | E30: ГРК | F30: 149 | G30: 103 | H30: =F30-G30 | I30: =IFERROR(G30/F30,"") | L30: 46138 | N30: 64
A31: ВЕСЕННЕ-ПОЛЕВЫЕ РАБОТЫ | B31: Предпосевная культивация | D31: Горох овощной (богара) | E31: ГРК | F31: 336 | G31: 336 | H31: =F31-G31 | I31: =IFERROR(G31/F31,"") | J31: 46026 | K31: 46101 | L31: 46085 | N31: 65
A32: ВЕСЕННЕ-ПОЛЕВЫЕ РАБОТЫ | B32: Предпосевная культивация | D32: Подсолнечник | E32: ГРК | F32: 486 | G32: 486 | H32: =F32-G32 | I32: =IFERROR(G32/F32,"") | J32: 46113 | K32: 46122 | L32: 46114 | M32: 46119 | N32: 66
A33: ВЕСЕННЕ-ПОЛЕВЫЕ РАБОТЫ | B33: Предпосевная культивация | D33: Кукуруза на зерно | E33: ГРК | F33: 237 | G33: 237 | H33: =F33-G33 | I33: =IFERROR(G33/F33,"") | J33: 46122 | K33: 46127 | L33: 46130 | M33: 46130 | N33: 67
A34: ВЕСЕННЕ-ПОЛЕВЫЕ РАБОТЫ | B34: Предпосевная культивация | D34: кукуруза супер сладкая | E34: ГРК | F34: 59 | G34: 59 | H34: =F34-G34 | I34: =IFERROR(G34/F34,"") | L34: 46148 | N34: 68
A35: ВЕСЕННЕ-ПОЛЕВЫЕ РАБОТЫ | B35: Предпосевная культивация | D35: Подсолнечник товарный | E35: ГРК | F35: 547 | G35: 547 | H35: =F35-G35 | I35: =IFERROR(G35/F35,"") | L35: 46117 | N35: 69
A36: ВЕСЕННЕ-ПОЛЕВЫЕ РАБОТЫ | B36: Сев горошка | D36: Горох овощной (богара) | E36: ГРК | F36: 778 | G36: 778 | H36: =F36-G36 | I36: =IFERROR(G36/F36,"") | J36: 46082 | K36: 46116 | L36: 46082 | M36: 46146 | N36: 51
A37: ВЕСЕННЕ-ПОЛЕВЫЕ РАБОТЫ | B37: Сев горошка | D37: Горох овощной (полив) | E37: ГРК | F37: 420 | G37: 420 | H37: =F37-G37 | I37: =IFERROR(G37/F37,"") | J37: 46111 | K37: 46147 | L37: 46113 | M37: 46148 | N37: 52
A38: ВЕСЕННЕ-ПОЛЕВЫЕ РАБОТЫ | B38: Сев горошка | D38: Горох овощной (полив) | E38: АгроЛидер | F38: 269 | G38: 269 | H38: =F38-G38 | I38: =IFERROR(G38/F38,"") | J38: 46117 | K38: 46124 | L38: 46117 | M38: 46128 | N38: 53
A39: ВЕСЕННЕ-ПОЛЕВЫЕ РАБОТЫ | B39: Сев горошка | D39: Горох овощной (полив) | E39: Колос | F39: 440.16 | G39: 440.1 | H39: =F39-G39 | I39: =IFERROR(G39/F39,"") | J39: 46125 | K39: 46138 | L39: 46129 | M39: 46141 | N39: 54
A40: ВЕСЕННЕ-ПОЛЕВЫЕ РАБОТЫ | B40: Сев зерновых | D40: Подсолнечник товарный | E40: ГРК | F40: 910 | G40: 910 | H40: =F40-G40 | I40: =IFERROR(G40/F40,"") | L40: 46117 | M40: 46131 | N40: 56
A41: ВЕСЕННЕ-ПОЛЕВЫЕ РАБОТЫ | B41: Сев зерновых | D41: Кукуруза на зерно | E41: ГРК | F41: 237 | G41: 237 | H41: =F41-G41 | I41: =IFERROR(G41/F41,"") | L41: 46130 | M41: 46132 | N41: 57
...

Sheet Выработка
A1: ВЫРАБОТКА ПО ДНЯМ — длинная таблица
A2: Одна строка = один день по одному срезу. Источник для сводных формул.
A4: Дата | B4: День | C4: Вид работ | D4: Культура | E4: Предприятие | F4: Га за день
A5: 46045 | B5: пт | C5: Глубокое рыхление 40-45 | D5: Подсолнечник гибридный | E5: ГРК | F5: 2
A6: 46080 | B6: пт | C6: Внесение мин.удобрений №1 | D6: Пшеница озимая | E6: ГРК | F6: 594
A7: 46081 | B7: сб | C7: Внесение мин.удобрений №1 | D7: Пшеница озимая | E7: ГРК | F7: 925
A8: 46082 | B8: вс | C8: Внесение мин.удобрений №1 | D8: Пшеница озимая | E8: ГРК | F8: 971
A9: 46082 | B9: вс | C9: Сев горошка | D9: Горох овощной (богара) | E9: ГРК | F9: 19
A10: 46083 | B10: пн | C10: Внесение мин.удобрений №1 | D10: Пшеница озимая | E10: ГРК | F10: 950
A11: 46083 | B11: пн | C11: Сев горошка | D11: Горох овощной (богара) | E11: ГРК | F11: 39
A12: 46084 | B12: вт | C12: Внесение мин.удобрений №1 | D12: Пшеница озимая | E12: ГРК | F12: 358
A13: 46084 | B13: вт | C13: Внесение мин.удобрений №1 | D13: Рапс озимый | E13: ГРК | F13: 251
A14: 46084 | B14: вт | C14: Прикатывание до всходов | D14: Горох овощной (богара) | E14: ГРК | F14: 75
A15: 46084 | B15: вт | C15: Сев горошка | D15: Горох овощной (богара) | E15: ГРК | F15: 53
A16: 46085 | B16: ср | C16: Глубокое рыхление 40-45 | D16: Подсолнечник гибридный | E16: ГРК | F16: 1
... A254: 46166 | B254: вс | C254: Хим обработка №2 | D254: Пшеница озимая | E254: ГРК | F254: 216
